30
Traceback (most recent call last):
  File "/Users/josephinewang/Desktop/INtro to ML/.venv/lib/python3.10/site-packages/pandas/core/indexes/base.py", line 3805, in get_loc
    return self._engine.get_loc(casted_key)
  File "index.pyx", line 167, in pandas._libs.index.IndexEngine.get_loc
  File "index.pyx", line 196, in pandas._libs.index.IndexEngine.get_loc
  File "pandas/_libs/hashtable_class_helper.pxi", line 7081, in pandas._libs.hashtable.PyObjectHashTable.get_item
  File "pandas/_libs/hashtable_class_helper.pxi", line 7089, in pandas._libs.hashtable.PyObjectHashTable.get_item
KeyError: 1

The above exception was the direct cause of the following exception:

Traceback (most recent call last):
  File "/Users/josephinewang/Desktop/INtro to ML/CMPM-17-FinalPro/TestLoop2.py", line 96, in <module>
    for inputs, outputs in train_loader:
  File "/Users/josephinewang/Desktop/INtro to ML/.venv/lib/python3.10/site-packages/torch/utils/data/dataloader.py", line 708, in __next__
    data = self._next_data()
  File "/Users/josephinewang/Desktop/INtro to ML/.venv/lib/python3.10/site-packages/torch/utils/data/dataloader.py", line 764, in _next_data
    data = self._dataset_fetcher.fetch(index)  # may raise StopIteration
  File "/Users/josephinewang/Desktop/INtro to ML/.venv/lib/python3.10/site-packages/torch/utils/data/_utils/fetch.py", line 52, in fetch
    data = [self.dataset[idx] for idx in possibly_batched_index]
  File "/Users/josephinewang/Desktop/INtro to ML/.venv/lib/python3.10/site-packages/torch/utils/data/_utils/fetch.py", line 52, in <listcomp>
    data = [self.dataset[idx] for idx in possibly_batched_index]
  File "/Users/josephinewang/Desktop/INtro to ML/CMPM-17-FinalPro/TestLoop2.py", line 44, in __getitem__
    output = self.values.loc[idx,1]
  File "/Users/josephinewang/Desktop/INtro to ML/.venv/lib/python3.10/site-packages/pandas/core/indexing.py", line 1183, in __getitem__
    return self.obj._get_value(*key, takeable=self._takeable)
  File "/Users/josephinewang/Desktop/INtro to ML/.venv/lib/python3.10/site-packages/pandas/core/frame.py", line 4214, in _get_value
    series = self._get_item_cache(col)
  File "/Users/josephinewang/Desktop/INtro to ML/.venv/lib/python3.10/site-packages/pandas/core/frame.py", line 4638, in _get_item_cache
    loc = self.columns.get_loc(item)
  File "/Users/josephinewang/Desktop/INtro to ML/.venv/lib/python3.10/site-packages/pandas/core/indexes/base.py", line 3812, in get_loc
    raise KeyError(key) from err
KeyError: 1
